C:\RESTAPI\api>python manage.py runserver
Watching for file changes with StatReloader
Performing system checks...

Exception in thread django-main-thread:
Traceback (most recent call last):
  File "C:\Users\azqoul\AppData\Local\Programs\Python\Python38-32\lib\threading.py", line 932, in _bootstrap_inner
    self.run()
  File "C:\Users\azqoul\AppData\Local\Programs\Python\Python38-32\lib\threading.py", line 870, in run
    self._target(*self._args, **self._kwargs)
  File "C:\Users\azqoul\AppData\Local\Programs\Python\Python38-32\lib\site-packages\django\utils\autoreload.py", line 53, in wrapper
    fn(*args, **kwargs)
  File "C:\Users\azqoul\AppData\Local\Programs\Python\Python38-32\lib\site-packages\django\core\management\commands\runserver.py", line 117, in inner_run
    self.check(display_num_errors=True)
  File "C:\Users\azqoul\AppData\Local\Programs\Python\Python38-32\lib\site-packages\django\core\management\base.py", line 392, in check
    all_issues = self._run_checks(
  File "C:\Users\azqoul\AppData\Local\Programs\Python\Python38-32\lib\site-packages\django\core\management\base.py", line 382, in _run_checks
    return checks.run_checks(**kwargs)
  File "C:\Users\azqoul\AppData\Local\Programs\Python\Python38-32\lib\site-packages\django\core\checks\registry.py", line 72, in run_checks
    new_errors = check(app_configs=app_configs)
  File "C:\Users\azqoul\AppData\Local\Programs\Python\Python38-32\lib\site-packages\django\core\checks\urls.py", line 13, in check_url_config
    return check_resolver(resolver)
  File "C:\Users\azqoul\AppData\Local\Programs\Python\Python38-32\lib\site-packages\django\core\checks\urls.py", line 23, in check_resolver
    return check_method()
  File "C:\Users\azqoul\AppData\Local\Programs\Python\Python38-32\lib\site-packages\django\urls\resolvers.py", line 407, in check
    for pattern in self.url_patterns:
  File "C:\Users\azqoul\AppData\Local\Programs\Python\Python38-32\lib\site-packages\django\utils\functional.py", line 48, in __get__
    res = instance.__dict__[self.name] = self.func(instance)
  File "C:\Users\azqoul\AppData\Local\Programs\Python\Python38-32\lib\site-packages\django\urls\resolvers.py", line 588, in url_patterns
    patterns = getattr(self.urlconf_module, "urlpatterns", self.urlconf_module)
  File "C:\Users\azqoul\AppData\Local\Programs\Python\Python38-32\lib\site-packages\django\utils\functional.py", line 48, in __get__
    res = instance.__dict__[self.name] = self.func(instance)
  File "C:\Users\azqoul\AppData\Local\Programs\Python\Python38-32\lib\site-packages\django\urls\resolvers.py", line 581, in urlconf_module
    return import_module(self.urlconf_name)
  File "C:\Users\azqoul\AppData\Local\Programs\Python\Python38-32\lib\importlib\__init__.py", line 127, in import_module
    return _bootstrap._gcd_import(name[level:], package, level)
  File "<frozen importlib._bootstrap>", line 1014, in _gcd_import
  File "<frozen importlib._bootstrap>", line 991, in _find_and_load
  File "<frozen importlib._bootstrap>", line 975, in _find_and_load_unlocked
  File "<frozen importlib._bootstrap>", line 671, in _load_unlocked
  File "<frozen importlib._bootstrap_external>", line 783, in exec_module
  File "<frozen importlib._bootstrap>", line 219, in _call_with_frames_removed
  File "C:\RESTAPI\api\api\urls.py", line 7, in <module>
    path('',include('myapp.urls')),
  File "C:\Users\azqoul\AppData\Local\Programs\Python\Python38-32\lib\site-packages\django\urls\conf.py", line 34, in include
    urlconf_module = import_module(urlconf_module)
  File "C:\Users\azqoul\AppData\Local\Programs\Python\Python38-32\lib\importlib\__init__.py", line 127, in import_module
    return _bootstrap._gcd_import(name[level:], package, level)
  File "<frozen importlib._bootstrap>", line 1014, in _gcd_import
  File "<frozen importlib._bootstrap>", line 991, in _find_and_load
  File "<frozen importlib._bootstrap>", line 975, in _find_and_load_unlocked
  File "<frozen importlib._bootstrap>", line 671, in _load_unlocked
  File "<frozen importlib._bootstrap_external>", line 783, in exec_module
  File "<frozen importlib._bootstrap>", line 219, in _call_with_frames_removed
  File "C:\RESTAPI\api\myapp\urls.py", line 5, in <module>
    r.register('',student_list)
  File "C:\Users\azqoul\AppData\Local\Programs\Python\Python38-32\lib\site-packages\rest_framework\routers.py", line 55, in register
    basename = self.get_default_basename(viewset)
  File "C:\Users\azqoul\AppData\Local\Programs\Python\Python38-32\lib\site-packages\rest_framework\routers.py", line 138, in get_default_basename
    assert queryset is not None, '`basename` argument not specified, and could ' \
AssertionError: `basename` argument not specified, and could not automatically determine the name from the viewset, as it does not have a `.queryset` attribute.

C:\RESTAPI\api>

